
[Failure instance: Traceback: <class 'pymysql.err.IntegrityError'>: (1048, "Column 'modifiedTime' cannot be null")
/usr/local/python3/lib/python3.6/threading.py:916:_bootstrap_inner
/usr/local/python3/lib/python3.6/threading.py:864:run
/root/.virtualenvs/py3/lib/python3.6/site-packages/Twisted-17.9.0-py3.6-linux-x86_64.egg/twisted/_threads/_threadworker.py:46:work
/root/.virtualenvs/py3/lib/python3.6/site-packages/Twisted-17.9.0-py3.6-linux-x86_64.egg/twisted/_threads/_team.py:190:doWork
--- <exception caught here> ---
/root/.virtualenvs/py3/lib/python3.6/site-packages/Twisted-17.9.0-py3.6-linux-x86_64.egg/twisted/python/threadpool.py:250:inContext
/root/.virtualenvs/py3/lib/python3.6/site-packages/Twisted-17.9.0-py3.6-linux-x86_64.egg/twisted/python/threadpool.py:266:<lambda>
/root/.virtualenvs/py3/lib/python3.6/site-packages/Twisted-17.9.0-py3.6-linux-x86_64.egg/twisted/python/context.py:122:callWithContext
/root/.virtualenvs/py3/lib/python3.6/site-packages/Twisted-17.9.0-py3.6-linux-x86_64.egg/twisted/python/context.py:85:callWithContext
/root/.virtualenvs/py3/lib/python3.6/site-packages/Twisted-17.9.0-py3.6-linux-x86_64.egg/twisted/enterprise/adbapi.py:477:_runInteraction
/root/.virtualenvs/py3/lib/python3.6/site-packages/Twisted-17.9.0-py3.6-linux-x86_64.egg/twisted/python/compat.py:463:reraise
/root/.virtualenvs/py3/lib/python3.6/site-packages/Twisted-17.9.0-py3.6-linux-x86_64.egg/twisted/enterprise/adbapi.py:467:_runInteraction
../find_keyword2/pipelines.py:58:do_insert
/root/.virtualenvs/py3/lib/python3.6/site-packages/pymysql/cursors.py:165:execute
/root/.virtualenvs/py3/lib/python3.6/site-packages/pymysql/cursors.py:321:_query
/root/.virtualenvs/py3/lib/python3.6/site-packages/pymysql/connections.py:860:query
/root/.virtualenvs/py3/lib/python3.6/site-packages/pymysql/connections.py:1061:_read_query_result
/root/.virtualenvs/py3/lib/python3.6/site-packages/pymysql/connections.py:1349:read
/root/.virtualenvs/py3/lib/python3.6/site-packages/pymysql/connections.py:1018:_read_packet
/root/.virtualenvs/py3/lib/python3.6/site-packages/pymysql/connections.py:384:check_error
/root/.virtualenvs/py3/lib/python3.6/site-packages/pymysql/err.py:107:raise_mysql_exception
]
[Failure instance: Traceback: <class 'pymysql.err.IntegrityError'>: (1048, "Column 'modifiedTime' cannot be null")
/usr/local/python3/lib/python3.6/threading.py:916:_bootstrap_inner
/usr/local/python3/lib/python3.6/threading.py:864:run
/root/.virtualenvs/py3/lib/python3.6/site-packages/Twisted-17.9.0-py3.6-linux-x86_64.egg/twisted/_threads/_threadworker.py:46:work
/root/.virtualenvs/py3/lib/python3.6/site-packages/Twisted-17.9.0-py3.6-linux-x86_64.egg/twisted/_threads/_team.py:190:doWork
--- <exception caught here> ---
/root/.virtualenvs/py3/lib/python3.6/site-packages/Twisted-17.9.0-py3.6-linux-x86_64.egg/twisted/python/threadpool.py:250:inContext
/root/.virtualenvs/py3/lib/python3.6/site-packages/Twisted-17.9.0-py3.6-linux-x86_64.egg/twisted/python/threadpool.py:266:<lambda>
/root/.virtualenvs/py3/lib/python3.6/site-packages/Twisted-17.9.0-py3.6-linux-x86_64.egg/twisted/python/context.py:122:callWithContext
/root/.virtualenvs/py3/lib/python3.6/site-packages/Twisted-17.9.0-py3.6-linux-x86_64.egg/twisted/python/context.py:85:callWithContext
/root/.virtualenvs/py3/lib/python3.6/site-packages/Twisted-17.9.0-py3.6-linux-x86_64.egg/twisted/enterprise/adbapi.py:477:_runInteraction
/root/.virtualenvs/py3/lib/python3.6/site-packages/Twisted-17.9.0-py3.6-linux-x86_64.egg/twisted/python/compat.py:463:reraise
/root/.virtualenvs/py3/lib/python3.6/site-packages/Twisted-17.9.0-py3.6-linux-x86_64.egg/twisted/enterprise/adbapi.py:467:_runInteraction
../find_keyword2/pipelines.py:58:do_insert
/root/.virtualenvs/py3/lib/python3.6/site-packages/pymysql/cursors.py:165:execute
/root/.virtualenvs/py3/lib/python3.6/site-packages/pymysql/cursors.py:321:_query
/root/.virtualenvs/py3/lib/python3.6/site-packages/pymysql/connections.py:860:query
/root/.virtualenvs/py3/lib/python3.6/site-packages/pymysql/connections.py:1061:_read_query_result
/root/.virtualenvs/py3/lib/python3.6/site-packages/pymysql/connections.py:1349:read
/root/.virtualenvs/py3/lib/python3.6/site-packages/pymysql/connections.py:1018:_read_packet
/root/.virtualenvs/py3/lib/python3.6/site-packages/pymysql/connections.py:384:check_error
/root/.virtualenvs/py3/lib/python3.6/site-packages/pymysql/err.py:107:raise_mysql_exception
]
[Failure instance: Traceback: <class 'pymysql.err.IntegrityError'>: (1048, "Column 'modifiedTime' cannot be null")
/usr/local/python3/lib/python3.6/threading.py:916:_bootstrap_inner
/usr/local/python3/lib/python3.6/threading.py:864:run
/root/.virtualenvs/py3/lib/python3.6/site-packages/Twisted-17.9.0-py3.6-linux-x86_64.egg/twisted/_threads/_threadworker.py:46:work
/root/.virtualenvs/py3/lib/python3.6/site-packages/Twisted-17.9.0-py3.6-linux-x86_64.egg/twisted/_threads/_team.py:190:doWork
--- <exception caught here> ---
/root/.virtualenvs/py3/lib/python3.6/site-packages/Twisted-17.9.0-py3.6-linux-x86_64.egg/twisted/python/threadpool.py:250:inContext
/root/.virtualenvs/py3/lib/python3.6/site-packages/Twisted-17.9.0-py3.6-linux-x86_64.egg/twisted/python/threadpool.py:266:<lambda>
/root/.virtualenvs/py3/lib/python3.6/site-packages/Twisted-17.9.0-py3.6-linux-x86_64.egg/twisted/python/context.py:122:callWithContext
/root/.virtualenvs/py3/lib/python3.6/site-packages/Twisted-17.9.0-py3.6-linux-x86_64.egg/twisted/python/context.py:85:callWithContext
/root/.virtualenvs/py3/lib/python3.6/site-packages/Twisted-17.9.0-py3.6-linux-x86_64.egg/twisted/enterprise/adbapi.py:477:_runInteraction
/root/.virtualenvs/py3/lib/python3.6/site-packages/Twisted-17.9.0-py3.6-linux-x86_64.egg/twisted/python/compat.py:463:reraise
/root/.virtualenvs/py3/lib/python3.6/site-packages/Twisted-17.9.0-py3.6-linux-x86_64.egg/twisted/enterprise/adbapi.py:467:_runInteraction
../find_keyword2/pipelines.py:58:do_insert
/root/.virtualenvs/py3/lib/python3.6/site-packages/pymysql/cursors.py:165:execute
/root/.virtualenvs/py3/lib/python3.6/site-packages/pymysql/cursors.py:321:_query
/root/.virtualenvs/py3/lib/python3.6/site-packages/pymysql/connections.py:860:query
/root/.virtualenvs/py3/lib/python3.6/site-packages/pymysql/connections.py:1061:_read_query_result
/root/.virtualenvs/py3/lib/python3.6/site-packages/pymysql/connections.py:1349:read
/root/.virtualenvs/py3/lib/python3.6/site-packages/pymysql/connections.py:1018:_read_packet
/root/.virtualenvs/py3/lib/python3.6/site-packages/pymysql/connections.py:384:check_error
/root/.virtualenvs/py3/lib/python3.6/site-packages/pymysql/err.py:107:raise_mysql_exception
]
[Failure instance: Traceback: <class 'pymysql.err.IntegrityError'>: (1048, "Column 'modifiedTime' cannot be null")
/usr/local/python3/lib/python3.6/threading.py:916:_bootstrap_inner
/usr/local/python3/lib/python3.6/threading.py:864:run
/root/.virtualenvs/py3/lib/python3.6/site-packages/Twisted-17.9.0-py3.6-linux-x86_64.egg/twisted/_threads/_threadworker.py:46:work
/root/.virtualenvs/py3/lib/python3.6/site-packages/Twisted-17.9.0-py3.6-linux-x86_64.egg/twisted/_threads/_team.py:190:doWork
--- <exception caught here> ---
/root/.virtualenvs/py3/lib/python3.6/site-packages/Twisted-17.9.0-py3.6-linux-x86_64.egg/twisted/python/threadpool.py:250:inContext
/root/.virtualenvs/py3/lib/python3.6/site-packages/Twisted-17.9.0-py3.6-linux-x86_64.egg/twisted/python/threadpool.py:266:<lambda>
/root/.virtualenvs/py3/lib/python3.6/site-packages/Twisted-17.9.0-py3.6-linux-x86_64.egg/twisted/python/context.py:122:callWithContext
/root/.virtualenvs/py3/lib/python3.6/site-packages/Twisted-17.9.0-py3.6-linux-x86_64.egg/twisted/python/context.py:85:callWithContext
/root/.virtualenvs/py3/lib/python3.6/site-packages/Twisted-17.9.0-py3.6-linux-x86_64.egg/twisted/enterprise/adbapi.py:477:_runInteraction
/root/.virtualenvs/py3/lib/python3.6/site-packages/Twisted-17.9.0-py3.6-linux-x86_64.egg/twisted/python/compat.py:463:reraise
/root/.virtualenvs/py3/lib/python3.6/site-packages/Twisted-17.9.0-py3.6-linux-x86_64.egg/twisted/enterprise/adbapi.py:467:_runInteraction
../find_keyword2/pipelines.py:58:do_insert
/root/.virtualenvs/py3/lib/python3.6/site-packages/pymysql/cursors.py:165:execute
/root/.virtualenvs/py3/lib/python3.6/site-packages/pymysql/cursors.py:321:_query
/root/.virtualenvs/py3/lib/python3.6/site-packages/pymysql/connections.py:860:query
/root/.virtualenvs/py3/lib/python3.6/site-packages/pymysql/connections.py:1061:_read_query_result
/root/.virtualenvs/py3/lib/python3.6/site-packages/pymysql/connections.py:1349:read
/root/.virtualenvs/py3/lib/python3.6/site-packages/pymysql/connections.py:1018:_read_packet
/root/.virtualenvs/py3/lib/python3.6/site-packages/pymysql/connections.py:384:check_error
/root/.virtualenvs/py3/lib/python3.6/site-packages/pymysql/err.py:107:raise_mysql_exception
]
[Failure instance: Traceback: <class 'pymysql.err.IntegrityError'>: (1048, "Column 'modifiedTime' cannot be null")
/usr/local/python3/lib/python3.6/threading.py:916:_bootstrap_inner
/usr/local/python3/lib/python3.6/threading.py:864:run
/root/.virtualenvs/py3/lib/python3.6/site-packages/Twisted-17.9.0-py3.6-linux-x86_64.egg/twisted/_threads/_threadworker.py:46:work
/root/.virtualenvs/py3/lib/python3.6/site-packages/Twisted-17.9.0-py3.6-linux-x86_64.egg/twisted/_threads/_team.py:190:doWork
--- <exception caught here> ---
/root/.virtualenvs/py3/lib/python3.6/site-packages/Twisted-17.9.0-py3.6-linux-x86_64.egg/twisted/python/threadpool.py:250:inContext
/root/.virtualenvs/py3/lib/python3.6/site-packages/Twisted-17.9.0-py3.6-linux-x86_64.egg/twisted/python/threadpool.py:266:<lambda>
/root/.virtualenvs/py3/lib/python3.6/site-packages/Twisted-17.9.0-py3.6-linux-x86_64.egg/twisted/python/context.py:122:callWithContext
/root/.virtualenvs/py3/lib/python3.6/site-packages/Twisted-17.9.0-py3.6-linux-x86_64.egg/twisted/python/context.py:85:callWithContext
/root/.virtualenvs/py3/lib/python3.6/site-packages/Twisted-17.9.0-py3.6-linux-x86_64.egg/twisted/enterprise/adbapi.py:477:_runInteraction
/root/.virtualenvs/py3/lib/python3.6/site-packages/Twisted-17.9.0-py3.6-linux-x86_64.egg/twisted/python/compat.py:463:reraise
/root/.virtualenvs/py3/lib/python3.6/site-packages/Twisted-17.9.0-py3.6-linux-x86_64.egg/twisted/enterprise/adbapi.py:467:_runInteraction
../find_keyword2/pipelines.py:58:do_insert
/root/.virtualenvs/py3/lib/python3.6/site-packages/pymysql/cursors.py:165:execute
/root/.virtualenvs/py3/lib/python3.6/site-packages/pymysql/cursors.py:321:_query
/root/.virtualenvs/py3/lib/python3.6/site-packages/pymysql/connections.py:860:query
/root/.virtualenvs/py3/lib/python3.6/site-packages/pymysql/connections.py:1061:_read_query_result
/root/.virtualenvs/py3/lib/python3.6/site-packages/pymysql/connections.py:1349:read
/root/.virtualenvs/py3/lib/python3.6/site-packages/pymysql/connections.py:1018:_read_packet
/root/.virtualenvs/py3/lib/python3.6/site-packages/pymysql/connections.py:384:check_error
/root/.virtualenvs/py3/lib/python3.6/site-packages/pymysql/err.py:107:raise_mysql_exception
]
[Failure instance: Traceback: <class 'pymysql.err.IntegrityError'>: (1048, "Column 'modifiedTime' cannot be null")
/usr/local/python3/lib/python3.6/threading.py:916:_bootstrap_inner
/usr/local/python3/lib/python3.6/threading.py:864:run
/root/.virtualenvs/py3/lib/python3.6/site-packages/Twisted-17.9.0-py3.6-linux-x86_64.egg/twisted/_threads/_threadworker.py:46:work
/root/.virtualenvs/py3/lib/python3.6/site-packages/Twisted-17.9.0-py3.6-linux-x86_64.egg/twisted/_threads/_team.py:190:doWork
--- <exception caught here> ---
/root/.virtualenvs/py3/lib/python3.6/site-packages/Twisted-17.9.0-py3.6-linux-x86_64.egg/twisted/python/threadpool.py:250:inContext
/root/.virtualenvs/py3/lib/python3.6/site-packages/Twisted-17.9.0-py3.6-linux-x86_64.egg/twisted/python/threadpool.py:266:<lambda>
/root/.virtualenvs/py3/lib/python3.6/site-packages/Twisted-17.9.0-py3.6-linux-x86_64.egg/twisted/python/context.py:122:callWithContext
/root/.virtualenvs/py3/lib/python3.6/site-packages/Twisted-17.9.0-py3.6-linux-x86_64.egg/twisted/python/context.py:85:callWithContext
/root/.virtualenvs/py3/lib/python3.6/site-packages/Twisted-17.9.0-py3.6-linux-x86_64.egg/twisted/enterprise/adbapi.py:477:_runInteraction
/root/.virtualenvs/py3/lib/python3.6/site-packages/Twisted-17.9.0-py3.6-linux-x86_64.egg/twisted/python/compat.py:463:reraise
/root/.virtualenvs/py3/lib/python3.6/site-packages/Twisted-17.9.0-py3.6-linux-x86_64.egg/twisted/enterprise/adbapi.py:467:_runInteraction
../find_keyword2/pipelines.py:58:do_insert
/root/.virtualenvs/py3/lib/python3.6/site-packages/pymysql/cursors.py:165:execute
/root/.virtualenvs/py3/lib/python3.6/site-packages/pymysql/cursors.py:321:_query
/root/.virtualenvs/py3/lib/python3.6/site-packages/pymysql/connections.py:860:query
/root/.virtualenvs/py3/lib/python3.6/site-packages/pymysql/connections.py:1061:_read_query_result
/root/.virtualenvs/py3/lib/python3.6/site-packages/pymysql/connections.py:1349:read
/root/.virtualenvs/py3/lib/python3.6/site-packages/pymysql/connections.py:1018:_read_packet
/root/.virtualenvs/py3/lib/python3.6/site-packages/pymysql/connections.py:384:check_error
/root/.virtualenvs/py3/lib/python3.6/site-packages/pymysql/err.py:107:raise_mysql_exception
]
[Failure instance: Traceback: <class 'pymysql.err.IntegrityError'>: (1048, "Column 'modifiedTime' cannot be null")
/usr/local/python3/lib/python3.6/threading.py:916:_bootstrap_inner
/usr/local/python3/lib/python3.6/threading.py:864:run
/root/.virtualenvs/py3/lib/python3.6/site-packages/Twisted-17.9.0-py3.6-linux-x86_64.egg/twisted/_threads/_threadworker.py:46:work
/root/.virtualenvs/py3/lib/python3.6/site-packages/Twisted-17.9.0-py3.6-linux-x86_64.egg/twisted/_threads/_team.py:190:doWork
--- <exception caught here> ---
/root/.virtualenvs/py3/lib/python3.6/site-packages/Twisted-17.9.0-py3.6-linux-x86_64.egg/twisted/python/threadpool.py:250:inContext
/root/.virtualenvs/py3/lib/python3.6/site-packages/Twisted-17.9.0-py3.6-linux-x86_64.egg/twisted/python/threadpool.py:266:<lambda>
/root/.virtualenvs/py3/lib/python3.6/site-packages/Twisted-17.9.0-py3.6-linux-x86_64.egg/twisted/python/context.py:122:callWithContext
/root/.virtualenvs/py3/lib/python3.6/site-packages/Twisted-17.9.0-py3.6-linux-x86_64.egg/twisted/python/context.py:85:callWithContext
/root/.virtualenvs/py3/lib/python3.6/site-packages/Twisted-17.9.0-py3.6-linux-x86_64.egg/twisted/enterprise/adbapi.py:477:_runInteraction
/root/.virtualenvs/py3/lib/python3.6/site-packages/Twisted-17.9.0-py3.6-linux-x86_64.egg/twisted/python/compat.py:463:reraise
/root/.virtualenvs/py3/lib/python3.6/site-packages/Twisted-17.9.0-py3.6-linux-x86_64.egg/twisted/enterprise/adbapi.py:467:_runInteraction
../find_keyword2/pipelines.py:58:do_insert
/root/.virtualenvs/py3/lib/python3.6/site-packages/pymysql/cursors.py:165:execute
/root/.virtualenvs/py3/lib/python3.6/site-packages/pymysql/cursors.py:321:_query
/root/.virtualenvs/py3/lib/python3.6/site-packages/pymysql/connections.py:860:query
/root/.virtualenvs/py3/lib/python3.6/site-packages/pymysql/connections.py:1061:_read_query_result
/root/.virtualenvs/py3/lib/python3.6/site-packages/pymysql/connections.py:1349:read
/root/.virtualenvs/py3/lib/python3.6/site-packages/pymysql/connections.py:1018:_read_packet
/root/.virtualenvs/py3/lib/python3.6/site-packages/pymysql/connections.py:384:check_error
/root/.virtualenvs/py3/lib/python3.6/site-packages/pymysql/err.py:107:raise_mysql_exception
]
[Failure instance: Traceback: <class 'pymysql.err.IntegrityError'>: (1048, "Column 'modifiedTime' cannot be null")
/usr/local/python3/lib/python3.6/threading.py:916:_bootstrap_inner
/usr/local/python3/lib/python3.6/threading.py:864:run
/root/.virtualenvs/py3/lib/python3.6/site-packages/Twisted-17.9.0-py3.6-linux-x86_64.egg/twisted/_threads/_threadworker.py:46:work
/root/.virtualenvs/py3/lib/python3.6/site-packages/Twisted-17.9.0-py3.6-linux-x86_64.egg/twisted/_threads/_team.py:190:doWork
--- <exception caught here> ---
/root/.virtualenvs/py3/lib/python3.6/site-packages/Twisted-17.9.0-py3.6-linux-x86_64.egg/twisted/python/threadpool.py:250:inContext
/root/.virtualenvs/py3/lib/python3.6/site-packages/Twisted-17.9.0-py3.6-linux-x86_64.egg/twisted/python/threadpool.py:266:<lambda>
/root/.virtualenvs/py3/lib/python3.6/site-packages/Twisted-17.9.0-py3.6-linux-x86_64.egg/twisted/python/context.py:122:callWithContext
/root/.virtualenvs/py3/lib/python3.6/site-packages/Twisted-17.9.0-py3.6-linux-x86_64.egg/twisted/python/context.py:85:callWithContext
/root/.virtualenvs/py3/lib/python3.6/site-packages/Twisted-17.9.0-py3.6-linux-x86_64.egg/twisted/enterprise/adbapi.py:477:_runInteraction
/root/.virtualenvs/py3/lib/python3.6/site-packages/Twisted-17.9.0-py3.6-linux-x86_64.egg/twisted/python/compat.py:463:reraise
/root/.virtualenvs/py3/lib/python3.6/site-packages/Twisted-17.9.0-py3.6-linux-x86_64.egg/twisted/enterprise/adbapi.py:467:_runInteraction
../find_keyword2/pipelines.py:58:do_insert
/root/.virtualenvs/py3/lib/python3.6/site-packages/pymysql/cursors.py:165:execute
/root/.virtualenvs/py3/lib/python3.6/site-packages/pymysql/cursors.py:321:_query
/root/.virtualenvs/py3/lib/python3.6/site-packages/pymysql/connections.py:860:query
/root/.virtualenvs/py3/lib/python3.6/site-packages/pymysql/connections.py:1061:_read_query_result
/root/.virtualenvs/py3/lib/python3.6/site-packages/pymysql/connections.py:1349:read
/root/.virtualenvs/py3/lib/python3.6/site-packages/pymysql/connections.py:1018:_read_packet
/root/.virtualenvs/py3/lib/python3.6/site-packages/pymysql/connections.py:384:check_error
/root/.virtualenvs/py3/lib/python3.6/site-packages/pymysql/err.py:107:raise_mysql_exception
]
[Failure instance: Traceback: <class 'pymysql.err.IntegrityError'>: (1048, "Column 'modifiedTime' cannot be null")
/usr/local/python3/lib/python3.6/threading.py:916:_bootstrap_inner
/usr/local/python3/lib/python3.6/threading.py:864:run
/root/.virtualenvs/py3/lib/python3.6/site-packages/Twisted-17.9.0-py3.6-linux-x86_64.egg/twisted/_threads/_threadworker.py:46:work
/root/.virtualenvs/py3/lib/python3.6/site-packages/Twisted-17.9.0-py3.6-linux-x86_64.egg/twisted/_threads/_team.py:190:doWork
--- <exception caught here> ---
/root/.virtualenvs/py3/lib/python3.6/site-packages/Twisted-17.9.0-py3.6-linux-x86_64.egg/twisted/python/threadpool.py:250:inContext
/root/.virtualenvs/py3/lib/python3.6/site-packages/Twisted-17.9.0-py3.6-linux-x86_64.egg/twisted/python/threadpool.py:266:<lambda>
/root/.virtualenvs/py3/lib/python3.6/site-packages/Twisted-17.9.0-py3.6-linux-x86_64.egg/twisted/python/context.py:122:callWithContext
/root/.virtualenvs/py3/lib/python3.6/site-packages/Twisted-17.9.0-py3.6-linux-x86_64.egg/twisted/python/context.py:85:callWithContext
/root/.virtualenvs/py3/lib/python3.6/site-packages/Twisted-17.9.0-py3.6-linux-x86_64.egg/twisted/enterprise/adbapi.py:477:_runInteraction
/root/.virtualenvs/py3/lib/python3.6/site-packages/Twisted-17.9.0-py3.6-linux-x86_64.egg/twisted/python/compat.py:463:reraise
/root/.virtualenvs/py3/lib/python3.6/site-packages/Twisted-17.9.0-py3.6-linux-x86_64.egg/twisted/enterprise/adbapi.py:467:_runInteraction
../find_keyword2/pipelines.py:58:do_insert
/root/.virtualenvs/py3/lib/python3.6/site-packages/pymysql/cursors.py:165:execute
/root/.virtualenvs/py3/lib/python3.6/site-packages/pymysql/cursors.py:321:_query
/root/.virtualenvs/py3/lib/python3.6/site-packages/pymysql/connections.py:860:query
/root/.virtualenvs/py3/lib/python3.6/site-packages/pymysql/connections.py:1061:_read_query_result
/root/.virtualenvs/py3/lib/python3.6/site-packages/pymysql/connections.py:1349:read
/root/.virtualenvs/py3/lib/python3.6/site-packages/pymysql/connections.py:1018:_read_packet
/root/.virtualenvs/py3/lib/python3.6/site-packages/pymysql/connections.py:384:check_error
/root/.virtualenvs/py3/lib/python3.6/site-packages/pymysql/err.py:107:raise_mysql_exception
]
[Failure instance: Traceback: <class 'pymysql.err.IntegrityError'>: (1048, "Column 'modifiedTime' cannot be null")
/usr/local/python3/lib/python3.6/threading.py:916:_bootstrap_inner
/usr/local/python3/lib/python3.6/threading.py:864:run
/root/.virtualenvs/py3/lib/python3.6/site-packages/Twisted-17.9.0-py3.6-linux-x86_64.egg/twisted/_threads/_threadworker.py:46:work
/root/.virtualenvs/py3/lib/python3.6/site-packages/Twisted-17.9.0-py3.6-linux-x86_64.egg/twisted/_threads/_team.py:190:doWork
--- <exception caught here> ---
/root/.virtualenvs/py3/lib/python3.6/site-packages/Twisted-17.9.0-py3.6-linux-x86_64.egg/twisted/python/threadpool.py:250:inContext
/root/.virtualenvs/py3/lib/python3.6/site-packages/Twisted-17.9.0-py3.6-linux-x86_64.egg/twisted/python/threadpool.py:266:<lambda>
/root/.virtualenvs/py3/lib/python3.6/site-packages/Twisted-17.9.0-py3.6-linux-x86_64.egg/twisted/python/context.py:122:callWithContext
/root/.virtualenvs/py3/lib/python3.6/site-packages/Twisted-17.9.0-py3.6-linux-x86_64.egg/twisted/python/context.py:85:callWithContext
/root/.virtualenvs/py3/lib/python3.6/site-packages/Twisted-17.9.0-py3.6-linux-x86_64.egg/twisted/enterprise/adbapi.py:477:_runInteraction
/root/.virtualenvs/py3/lib/python3.6/site-packages/Twisted-17.9.0-py3.6-linux-x86_64.egg/twisted/python/compat.py:463:reraise
/root/.virtualenvs/py3/lib/python3.6/site-packages/Twisted-17.9.0-py3.6-linux-x86_64.egg/twisted/enterprise/adbapi.py:467:_runInteraction
../find_keyword2/pipelines.py:58:do_insert
/root/.virtualenvs/py3/lib/python3.6/site-packages/pymysql/cursors.py:165:execute
/root/.virtualenvs/py3/lib/python3.6/site-packages/pymysql/cursors.py:321:_query
/root/.virtualenvs/py3/lib/python3.6/site-packages/pymysql/connections.py:860:query
/root/.virtualenvs/py3/lib/python3.6/site-packages/pymysql/connections.py:1061:_read_query_result
/root/.virtualenvs/py3/lib/python3.6/site-packages/pymysql/connections.py:1349:read
/root/.virtualenvs/py3/lib/python3.6/site-packages/pymysql/connections.py:1018:_read_packet
/root/.virtualenvs/py3/lib/python3.6/site-packages/pymysql/connections.py:384:check_error
/root/.virtualenvs/py3/lib/python3.6/site-packages/pymysql/err.py:107:raise_mysql_exception
]
[Failure instance: Traceback: <class 'pymysql.err.IntegrityError'>: (1048, "Column 'modifiedTime' cannot be null")
/usr/local/python3/lib/python3.6/threading.py:916:_bootstrap_inner
/usr/local/python3/lib/python3.6/threading.py:864:run
/root/.virtualenvs/py3/lib/python3.6/site-packages/Twisted-17.9.0-py3.6-linux-x86_64.egg/twisted/_threads/_threadworker.py:46:work
/root/.virtualenvs/py3/lib/python3.6/site-packages/Twisted-17.9.0-py3.6-linux-x86_64.egg/twisted/_threads/_team.py:190:doWork
--- <exception caught here> ---
/root/.virtualenvs/py3/lib/python3.6/site-packages/Twisted-17.9.0-py3.6-linux-x86_64.egg/twisted/python/threadpool.py:250:inContext
/root/.virtualenvs/py3/lib/python3.6/site-packages/Twisted-17.9.0-py3.6-linux-x86_64.egg/twisted/python/threadpool.py:266:<lambda>
/root/.virtualenvs/py3/lib/python3.6/site-packages/Twisted-17.9.0-py3.6-linux-x86_64.egg/twisted/python/context.py:122:callWithContext
/root/.virtualenvs/py3/lib/python3.6/site-packages/Twisted-17.9.0-py3.6-linux-x86_64.egg/twisted/python/context.py:85:callWithContext
/root/.virtualenvs/py3/lib/python3.6/site-packages/Twisted-17.9.0-py3.6-linux-x86_64.egg/twisted/enterprise/adbapi.py:477:_runInteraction
/root/.virtualenvs/py3/lib/python3.6/site-packages/Twisted-17.9.0-py3.6-linux-x86_64.egg/twisted/python/compat.py:463:reraise
/root/.virtualenvs/py3/lib/python3.6/site-packages/Twisted-17.9.0-py3.6-linux-x86_64.egg/twisted/enterprise/adbapi.py:467:_runInteraction
../find_keyword2/pipelines.py:58:do_insert
/root/.virtualenvs/py3/lib/python3.6/site-packages/pymysql/cursors.py:165:execute
/root/.virtualenvs/py3/lib/python3.6/site-packages/pymysql/cursors.py:321:_query
/root/.virtualenvs/py3/lib/python3.6/site-packages/pymysql/connections.py:860:query
/root/.virtualenvs/py3/lib/python3.6/site-packages/pymysql/connections.py:1061:_read_query_result
/root/.virtualenvs/py3/lib/python3.6/site-packages/pymysql/connections.py:1349:read
/root/.virtualenvs/py3/lib/python3.6/site-packages/pymysql/connections.py:1018:_read_packet
/root/.virtualenvs/py3/lib/python3.6/site-packages/pymysql/connections.py:384:check_error
/root/.virtualenvs/py3/lib/python3.6/site-packages/pymysql/err.py:107:raise_mysql_exception
]
[Failure instance: Traceback: <class 'pymysql.err.IntegrityError'>: (1048, "Column 'modifiedTime' cannot be null")
/usr/local/python3/lib/python3.6/threading.py:916:_bootstrap_inner
/usr/local/python3/lib/python3.6/threading.py:864:run
/root/.virtualenvs/py3/lib/python3.6/site-packages/Twisted-17.9.0-py3.6-linux-x86_64.egg/twisted/_threads/_threadworker.py:46:work
/root/.virtualenvs/py3/lib/python3.6/site-packages/Twisted-17.9.0-py3.6-linux-x86_64.egg/twisted/_threads/_team.py:190:doWork
--- <exception caught here> ---
/root/.virtualenvs/py3/lib/python3.6/site-packages/Twisted-17.9.0-py3.6-linux-x86_64.egg/twisted/python/threadpool.py:250:inContext
/root/.virtualenvs/py3/lib/python3.6/site-packages/Twisted-17.9.0-py3.6-linux-x86_64.egg/twisted/python/threadpool.py:266:<lambda>
/root/.virtualenvs/py3/lib/python3.6/site-packages/Twisted-17.9.0-py3.6-linux-x86_64.egg/twisted/python/context.py:122:callWithContext
/root/.virtualenvs/py3/lib/python3.6/site-packages/Twisted-17.9.0-py3.6-linux-x86_64.egg/twisted/python/context.py:85:callWithContext
/root/.virtualenvs/py3/lib/python3.6/site-packages/Twisted-17.9.0-py3.6-linux-x86_64.egg/twisted/enterprise/adbapi.py:477:_runInteraction
/root/.virtualenvs/py3/lib/python3.6/site-packages/Twisted-17.9.0-py3.6-linux-x86_64.egg/twisted/python/compat.py:463:reraise
/root/.virtualenvs/py3/lib/python3.6/site-packages/Twisted-17.9.0-py3.6-linux-x86_64.egg/twisted/enterprise/adbapi.py:467:_runInteraction
../find_keyword2/pipelines.py:58:do_insert
/root/.virtualenvs/py3/lib/python3.6/site-packages/pymysql/cursors.py:165:execute
/root/.virtualenvs/py3/lib/python3.6/site-packages/pymysql/cursors.py:321:_query
/root/.virtualenvs/py3/lib/python3.6/site-packages/pymysql/connections.py:860:query
/root/.virtualenvs/py3/lib/python3.6/site-packages/pymysql/connections.py:1061:_read_query_result
/root/.virtualenvs/py3/lib/python3.6/site-packages/pymysql/connections.py:1349:read
/root/.virtualenvs/py3/lib/python3.6/site-packages/pymysql/connections.py:1018:_read_packet
/root/.virtualenvs/py3/lib/python3.6/site-packages/pymysql/connections.py:384:check_error
/root/.virtualenvs/py3/lib/python3.6/site-packages/pymysql/err.py:107:raise_mysql_exception
]
[Failure instance: Traceback: <class 'pymysql.err.IntegrityError'>: (1048, "Column 'modifiedTime' cannot be null")
/usr/local/python3/lib/python3.6/threading.py:916:_bootstrap_inner
/usr/local/python3/lib/python3.6/threading.py:864:run
/root/.virtualenvs/py3/lib/python3.6/site-packages/Twisted-17.9.0-py3.6-linux-x86_64.egg/twisted/_threads/_threadworker.py:46:work
/root/.virtualenvs/py3/lib/python3.6/site-packages/Twisted-17.9.0-py3.6-linux-x86_64.egg/twisted/_threads/_team.py:190:doWork
--- <exception caught here> ---
/root/.virtualenvs/py3/lib/python3.6/site-packages/Twisted-17.9.0-py3.6-linux-x86_64.egg/twisted/python/threadpool.py:250:inContext
/root/.virtualenvs/py3/lib/python3.6/site-packages/Twisted-17.9.0-py3.6-linux-x86_64.egg/twisted/python/threadpool.py:266:<lambda>
/root/.virtualenvs/py3/lib/python3.6/site-packages/Twisted-17.9.0-py3.6-linux-x86_64.egg/twisted/python/context.py:122:callWithContext
/root/.virtualenvs/py3/lib/python3.6/site-packages/Twisted-17.9.0-py3.6-linux-x86_64.egg/twisted/python/context.py:85:callWithContext
/root/.virtualenvs/py3/lib/python3.6/site-packages/Twisted-17.9.0-py3.6-linux-x86_64.egg/twisted/enterprise/adbapi.py:477:_runInteraction
/root/.virtualenvs/py3/lib/python3.6/site-packages/Twisted-17.9.0-py3.6-linux-x86_64.egg/twisted/python/compat.py:463:reraise
/root/.virtualenvs/py3/lib/python3.6/site-packages/Twisted-17.9.0-py3.6-linux-x86_64.egg/twisted/enterprise/adbapi.py:467:_runInteraction
../find_keyword2/pipelines.py:58:do_insert
/root/.virtualenvs/py3/lib/python3.6/site-packages/pymysql/cursors.py:165:execute
/root/.virtualenvs/py3/lib/python3.6/site-packages/pymysql/cursors.py:321:_query
/root/.virtualenvs/py3/lib/python3.6/site-packages/pymysql/connections.py:860:query
/root/.virtualenvs/py3/lib/python3.6/site-packages/pymysql/connections.py:1061:_read_query_result
/root/.virtualenvs/py3/lib/python3.6/site-packages/pymysql/connections.py:1349:read
/root/.virtualenvs/py3/lib/python3.6/site-packages/pymysql/connections.py:1018:_read_packet
/root/.virtualenvs/py3/lib/python3.6/site-packages/pymysql/connections.py:384:check_error
/root/.virtualenvs/py3/lib/python3.6/site-packages/pymysql/err.py:107:raise_mysql_exception
]
[Failure instance: Traceback: <class 'pymysql.err.IntegrityError'>: (1048, "Column 'modifiedTime' cannot be null")
/usr/local/python3/lib/python3.6/threading.py:916:_bootstrap_inner
/usr/local/python3/lib/python3.6/threading.py:864:run
/root/.virtualenvs/py3/lib/python3.6/site-packages/Twisted-17.9.0-py3.6-linux-x86_64.egg/twisted/_threads/_threadworker.py:46:work
/root/.virtualenvs/py3/lib/python3.6/site-packages/Twisted-17.9.0-py3.6-linux-x86_64.egg/twisted/_threads/_team.py:190:doWork
--- <exception caught here> ---
/root/.virtualenvs/py3/lib/python3.6/site-packages/Twisted-17.9.0-py3.6-linux-x86_64.egg/twisted/python/threadpool.py:250:inContext
/root/.virtualenvs/py3/lib/python3.6/site-packages/Twisted-17.9.0-py3.6-linux-x86_64.egg/twisted/python/threadpool.py:266:<lambda>
/root/.virtualenvs/py3/lib/python3.6/site-packages/Twisted-17.9.0-py3.6-linux-x86_64.egg/twisted/python/context.py:122:callWithContext
/root/.virtualenvs/py3/lib/python3.6/site-packages/Twisted-17.9.0-py3.6-linux-x86_64.egg/twisted/python/context.py:85:callWithContext
/root/.virtualenvs/py3/lib/python3.6/site-packages/Twisted-17.9.0-py3.6-linux-x86_64.egg/twisted/enterprise/adbapi.py:477:_runInteraction
/root/.virtualenvs/py3/lib/python3.6/site-packages/Twisted-17.9.0-py3.6-linux-x86_64.egg/twisted/python/compat.py:463:reraise
/root/.virtualenvs/py3/lib/python3.6/site-packages/Twisted-17.9.0-py3.6-linux-x86_64.egg/twisted/enterprise/adbapi.py:467:_runInteraction
../find_keyword2/pipelines.py:58:do_insert
/root/.virtualenvs/py3/lib/python3.6/site-packages/pymysql/cursors.py:165:execute
/root/.virtualenvs/py3/lib/python3.6/site-packages/pymysql/cursors.py:321:_query
/root/.virtualenvs/py3/lib/python3.6/site-packages/pymysql/connections.py:860:query
/root/.virtualenvs/py3/lib/python3.6/site-packages/pymysql/connections.py:1061:_read_query_result
/root/.virtualenvs/py3/lib/python3.6/site-packages/pymysql/connections.py:1349:read
/root/.virtualenvs/py3/lib/python3.6/site-packages/pymysql/connections.py:1018:_read_packet
/root/.virtualenvs/py3/lib/python3.6/site-packages/pymysql/connections.py:384:check_error
/root/.virtualenvs/py3/lib/python3.6/site-packages/pymysql/err.py:107:raise_mysql_exception
]
[Failure instance: Traceback: <class 'pymysql.err.IntegrityError'>: (1048, "Column 'modifiedTime' cannot be null")
/usr/local/python3/lib/python3.6/threading.py:916:_bootstrap_inner
/usr/local/python3/lib/python3.6/threading.py:864:run
/root/.virtualenvs/py3/lib/python3.6/site-packages/Twisted-17.9.0-py3.6-linux-x86_64.egg/twisted/_threads/_threadworker.py:46:work
/root/.virtualenvs/py3/lib/python3.6/site-packages/Twisted-17.9.0-py3.6-linux-x86_64.egg/twisted/_threads/_team.py:190:doWork
--- <exception caught here> ---
/root/.virtualenvs/py3/lib/python3.6/site-packages/Twisted-17.9.0-py3.6-linux-x86_64.egg/twisted/python/threadpool.py:250:inContext
/root/.virtualenvs/py3/lib/python3.6/site-packages/Twisted-17.9.0-py3.6-linux-x86_64.egg/twisted/python/threadpool.py:266:<lambda>
/root/.virtualenvs/py3/lib/python3.6/site-packages/Twisted-17.9.0-py3.6-linux-x86_64.egg/twisted/python/context.py:122:callWithContext
/root/.virtualenvs/py3/lib/python3.6/site-packages/Twisted-17.9.0-py3.6-linux-x86_64.egg/twisted/python/context.py:85:callWithContext
/root/.virtualenvs/py3/lib/python3.6/site-packages/Twisted-17.9.0-py3.6-linux-x86_64.egg/twisted/enterprise/adbapi.py:477:_runInteraction
/root/.virtualenvs/py3/lib/python3.6/site-packages/Twisted-17.9.0-py3.6-linux-x86_64.egg/twisted/python/compat.py:463:reraise
/root/.virtualenvs/py3/lib/python3.6/site-packages/Twisted-17.9.0-py3.6-linux-x86_64.egg/twisted/enterprise/adbapi.py:467:_runInteraction
../find_keyword2/pipelines.py:58:do_insert
/root/.virtualenvs/py3/lib/python3.6/site-packages/pymysql/cursors.py:165:execute
/root/.virtualenvs/py3/lib/python3.6/site-packages/pymysql/cursors.py:321:_query
/root/.virtualenvs/py3/lib/python3.6/site-packages/pymysql/connections.py:860:query
/root/.virtualenvs/py3/lib/python3.6/site-packages/pymysql/connections.py:1061:_read_query_result
/root/.virtualenvs/py3/lib/python3.6/site-packages/pymysql/connections.py:1349:read
/root/.virtualenvs/py3/lib/python3.6/site-packages/pymysql/connections.py:1018:_read_packet
/root/.virtualenvs/py3/lib/python3.6/site-packages/pymysql/connections.py:384:check_error
/root/.virtualenvs/py3/lib/python3.6/site-packages/pymysql/err.py:107:raise_mysql_exception
]
[Failure instance: Traceback: <class 'pymysql.err.IntegrityError'>: (1048, "Column 'modifiedTime' cannot be null")
/usr/local/python3/lib/python3.6/threading.py:916:_bootstrap_inner
/usr/local/python3/lib/python3.6/threading.py:864:run
/root/.virtualenvs/py3/lib/python3.6/site-packages/Twisted-17.9.0-py3.6-linux-x86_64.egg/twisted/_threads/_threadworker.py:46:work
/root/.virtualenvs/py3/lib/python3.6/site-packages/Twisted-17.9.0-py3.6-linux-x86_64.egg/twisted/_threads/_team.py:190:doWork
--- <exception caught here> ---
/root/.virtualenvs/py3/lib/python3.6/site-packages/Twisted-17.9.0-py3.6-linux-x86_64.egg/twisted/python/threadpool.py:250:inContext
/root/.virtualenvs/py3/lib/python3.6/site-packages/Twisted-17.9.0-py3.6-linux-x86_64.egg/twisted/python/threadpool.py:266:<lambda>
/root/.virtualenvs/py3/lib/python3.6/site-packages/Twisted-17.9.0-py3.6-linux-x86_64.egg/twisted/python/context.py:122:callWithContext
/root/.virtualenvs/py3/lib/python3.6/site-packages/Twisted-17.9.0-py3.6-linux-x86_64.egg/twisted/python/context.py:85:callWithContext
/root/.virtualenvs/py3/lib/python3.6/site-packages/Twisted-17.9.0-py3.6-linux-x86_64.egg/twisted/enterprise/adbapi.py:477:_runInteraction
/root/.virtualenvs/py3/lib/python3.6/site-packages/Twisted-17.9.0-py3.6-linux-x86_64.egg/twisted/python/compat.py:463:reraise
/root/.virtualenvs/py3/lib/python3.6/site-packages/Twisted-17.9.0-py3.6-linux-x86_64.egg/twisted/enterprise/adbapi.py:467:_runInteraction
../find_keyword2/pipelines.py:58:do_insert
/root/.virtualenvs/py3/lib/python3.6/site-packages/pymysql/cursors.py:165:execute
/root/.virtualenvs/py3/lib/python3.6/site-packages/pymysql/cursors.py:321:_query
/root/.virtualenvs/py3/lib/python3.6/site-packages/pymysql/connections.py:860:query
/root/.virtualenvs/py3/lib/python3.6/site-packages/pymysql/connections.py:1061:_read_query_result
/root/.virtualenvs/py3/lib/python3.6/site-packages/pymysql/connections.py:1349:read
/root/.virtualenvs/py3/lib/python3.6/site-packages/pymysql/connections.py:1018:_read_packet
/root/.virtualenvs/py3/lib/python3.6/site-packages/pymysql/connections.py:384:check_error
/root/.virtualenvs/py3/lib/python3.6/site-packages/pymysql/err.py:107:raise_mysql_exception
]
[Failure instance: Traceback: <class 'pymysql.err.IntegrityError'>: (1048, "Column 'modifiedTime' cannot be null")
/usr/local/python3/lib/python3.6/threading.py:916:_bootstrap_inner
/usr/local/python3/lib/python3.6/threading.py:864:run
/root/.virtualenvs/py3/lib/python3.6/site-packages/Twisted-17.9.0-py3.6-linux-x86_64.egg/twisted/_threads/_threadworker.py:46:work
/root/.virtualenvs/py3/lib/python3.6/site-packages/Twisted-17.9.0-py3.6-linux-x86_64.egg/twisted/_threads/_team.py:190:doWork
--- <exception caught here> ---
/root/.virtualenvs/py3/lib/python3.6/site-packages/Twisted-17.9.0-py3.6-linux-x86_64.egg/twisted/python/threadpool.py:250:inContext
/root/.virtualenvs/py3/lib/python3.6/site-packages/Twisted-17.9.0-py3.6-linux-x86_64.egg/twisted/python/threadpool.py:266:<lambda>
/root/.virtualenvs/py3/lib/python3.6/site-packages/Twisted-17.9.0-py3.6-linux-x86_64.egg/twisted/python/context.py:122:callWithContext
/root/.virtualenvs/py3/lib/python3.6/site-packages/Twisted-17.9.0-py3.6-linux-x86_64.egg/twisted/python/context.py:85:callWithContext
/root/.virtualenvs/py3/lib/python3.6/site-packages/Twisted-17.9.0-py3.6-linux-x86_64.egg/twisted/enterprise/adbapi.py:477:_runInteraction
/root/.virtualenvs/py3/lib/python3.6/site-packages/Twisted-17.9.0-py3.6-linux-x86_64.egg/twisted/python/compat.py:463:reraise
/root/.virtualenvs/py3/lib/python3.6/site-packages/Twisted-17.9.0-py3.6-linux-x86_64.egg/twisted/enterprise/adbapi.py:467:_runInteraction
../find_keyword2/pipelines.py:58:do_insert
/root/.virtualenvs/py3/lib/python3.6/site-packages/pymysql/cursors.py:165:execute
/root/.virtualenvs/py3/lib/python3.6/site-packages/pymysql/cursors.py:321:_query
/root/.virtualenvs/py3/lib/python3.6/site-packages/pymysql/connections.py:860:query
/root/.virtualenvs/py3/lib/python3.6/site-packages/pymysql/connections.py:1061:_read_query_result
/root/.virtualenvs/py3/lib/python3.6/site-packages/pymysql/connections.py:1349:read
/root/.virtualenvs/py3/lib/python3.6/site-packages/pymysql/connections.py:1018:_read_packet
/root/.virtualenvs/py3/lib/python3.6/site-packages/pymysql/connections.py:384:check_error
/root/.virtualenvs/py3/lib/python3.6/site-packages/pymysql/err.py:107:raise_mysql_exception
]
